Workbook

Sheet 00_README
A1: ICT702 Task 2 — Growing Golf in Germany (v2, full source set)
A2: Data sources, definitions, reconciliation and workbook structure
A5: PURPOSE | B5: Data basis for an Excel dashboard supporting the executive board of the German Golf Federation (DGV) in strategic decisions aimed at increasing participation in golf. The twelve state golf associations are the secondary audience, as the layer that implements those decisions regionally.
A6: AUDIENCE | B6: Primary: the DGV executive board, which sets national participation strategy and allocates the programme budget. Secondary: the twelve state golf associations, which implement it regionally.
A7: PERIOD | B7: 2016–2025 for the core analysis; longer series where the sources allow.
A8: CENSUS DATES | B8: Players: 30 September. Facilities and member clubs: 31 December.
A10: SOURCES
A11: S1 | B11: Deutscher Golf Verband. (2017–2026). DGV-Statistiken 2016–2025 [Annual statistics, ten editions]. Wiesbaden: DGV. Files: statistiken/2016_… to statistiken/2025_…
A12: S2 | B12: Deutscher Golf Verband. (2026). Golf in Deutschland erreicht neue Höchstwerte [Press release, 21 January 2026].
A13: S3 | B13: Institut für Demoskopie Allensbach. (2025). Allensbacher Markt- und Werbeträgeranalyse (AWA 2025), via Statista [IDs 171038, 171039, 171147]. Base: German-speaking population aged 14+.
A14: S4 | B14: Deutscher Golf Verband, via Statista [IDs 5148, 6888, 6892, 6894, 6899, 6900, 6904, 214654].
A15: S5 | B15: The R&A. (2025). Global Golf Participation 2024 [Report, June 2025, excluding the USA and Mexico].
A16: S6 | B16: Statistisches Bundesamt. (2025). Bundesländer mit Hauptstädten nach Fläche, Bevölkerung und Bevölkerungsdichte am 31.12.2024 [2022 Census basis].
A17: S7 | B17: Statistisches Bundesamt. (2025). By 2035, one quarter of Germany's population will be aged 67 or over [Press release No. 446, 11 December 2025].
A18: S8 | B18: Huth, C., & Billion, F. (2022). Impacts of the COVID-19 pandemic on German golf – a comparison between club-owned and commercial golf clubs. Quality in Sport, 8(1), 21–27. https://doi.org/10.12775/QS.2022.08.01.002
A19: S9 | B19: The R&A. (2021). Women in Golf Charter — Impact studies [March 2021].
A20: S10 | B20: Deutscher Olympischer Sportbund. Bestandserhebung (as at 1 January 2025), cited in S1.
A21: S11 | B21: Okabe, M., & Ito, K. (2008). Color Universal Design (CUD). https://jfly.uni-koeln.de/color/
A22: S12 | B22: Camm, J. D., Cochran, J. J., Fry, M. J., & Ohlmann, J. W. (2021). Data visualization: Exploring and explaining with data (1st ed.). Cengage. [Course text underpinning ICT702 Modules 2–8]
... A27: COLOUR PALETTE | B27: Blue #0072B2 / Orange #E69F00 — Okabe-Ito pair, distinguishable under deuteranopia, protanopia and tritanopia (S11). Grey #999999 for context series.
A29: SHEET GUIDE
A30: 01_Timeseries | B30: Players, gender split, clubs and facilities 2016–2025
A31: 02_Age_Gender | B31: Eleven age bands by gender, 2016–2025 (wide, as published)
A33: 04_States | B33: State associations 2016 vs 2025, facilities, population, penetration
A36: 07_Funnel | B36: Allensbach awareness / interest / play funnel 2019–2025 (S3)
A37: 08_Europe | B37: R&A European benchmark: penetration, female share, courses (S5)
A38: 09_Federations
A39: 10_History
A40: 11_Metrics | B40: Derived metrics as live formulas, plus a waterfall-ready data block
A41: 12_Chart_Selection
A42: 13_Design_Rationale
A43: 20_Dashboard | B43: Dashboard with six visualisations
A45: CAVEAT — VcG | B45: The 'Vereinigung clubfreier Golfspieler' is a nationwide membership category, not a region. It is listed separately and excluded from all penetration metrics.
A46: CAVEAT — AWA BASE | B46: Allensbach surveys the German-speaking population aged 14 and over in private households; DGV membership covers all ages. The funnel therefore compares a survey population with an administrative count and indicates magnitude, not an exact rate.
A47: CAVEAT — 60+ | B47: The five-year senior bands (325,743) overlap the '61 and over' band (306,153). Do not add them.
A48: CAVEAT — FACILITIES | B48: Some year-on-year changes reflect reclassification in the DGV's records (e.g. merging a 9-hole and an 18-hole course into one 27-hole facility).
A49: CAVEAT — TERMS | B49: 'Registered membership' is not the same as 'person who plays golf'. Multiple memberships and casual play without club affiliation are not captured.
A50: AI DECLARATION | B50: Acknowledge any use of AI tools in the report, per UniSC requirements.
A52: CAVEAT — MAP LABELS | B52: Column A of 04_States uses Excel Geography data types so that a regional map can be drawn. Three associations that span two federal states resolve to the larger state only: Lower Saxony also covers Bremen, Rhineland-Palatinate also covers Saarland, and Saxony also covers Thüringen.
B53: All figures and population denominators cover the full combined territory, so the rates are correct for the association; only the map label is narrower. Membership is not published below association level in any source. State this in the report's limitations section.

Sheet 01_Timeseries
A1: Players, gender split, clubs and facilities, 2016–2025
A2: Sources: S1, S4
A4: Year | B4: Players | C4: Male | D4: Female | E4: Female share | F4: Change (abs.) | G4: Change (%) | H4: Clubs | I4: Facilities | J4: Players per facility | K4: Index (2016=100)
A5: 2016 | B5: 643158 | C5: 406551 | D5: 236607 | E5: =D5/B5 -> 0.36788316 | H5: 847 | I5: 732 | J5: =B5/I5 -> 878.63115 | K5: =B5/$B$5*100 -> 100
A6: 2017 | B6: 644943 | C6: 408960 | D6: 235983 | E6: =D6/B6 -> 0.36589745 | F6: =B6-B5 -> 1785 | G6: =IFERROR(F6/B5,"") -> 0.0027753678 | H6: 843 | I6: 731 | J6: =B6/I6 -> 882.27497 | K6: =B6/$B$5*100 -> 100.27754
A7: 2018 | B7: 642240 | C7: 408103 | D7: 234137 | E7: =D7/B7 -> 0.36456309 | F7: =B7-B6 -> -2703 | G7: =IFERROR(F7/B6,"") -> -0.004191068 | H7: 840 | I7: 730 | J7: =B7/I7 -> 879.78082 | K7: =B7/$B$5*100 -> 99.857267
A8: 2019 | B8: 642677 | C8: 409205 | D8: 233472 | E8: =D8/B8 -> 0.36328047 | F8: =B8-B7 -> 437 | G8: =IFERROR(F8/B7,"") -> 0.00068043099 | H8: 832 | I8: 722 | J8: =B8/I8 -> 890.13435 | K8: =B8/$B$5*100 -> 99.925213
A9: 2020 | B9: 651417 | C9: 416016 | D9: 235401 | E9: =D9/B9 -> 0.3613676 | F9: =B9-B8 -> 8740 | G9: =IFERROR(F9/B8,"") -> 0.013599366 | H9: 825 | I9: 720 | J9: =B9/I9 -> 904.74583 | K9: =B9/$B$5*100 -> 101.28413
A10: 2021 | B10: 673983 | C10: 431818 | D10: 242165 | E10: =D10/B10 -> 0.35930431 | F10: =B10-B9 -> 22566 | G10: =IFERROR(F10/B9,"") -> 0.034641405 | H10: 825 | I10: 720 | J10: =B10/I10 -> 936.0875 | K10: =B10/$B$5*100 -> 104.79276
A11: 2022 | B11: 682942 | C11: 438469 | D11: 244473 | E11: =D11/B11 -> 0.35797037 | F11: =B11-B10 -> 8959 | G11: =IFERROR(F11/B10,"") -> 0.01329262 | H11: 827 | I11: 729 | J11: =B11/I11 -> 936.8203 | K11: =B11/$B$5*100 -> 106.18573
A12: 2023 | B12: 682126 | C12: 439793 | D12: 242333 | E12: =D12/B12 -> 0.35526134 | F12: =B12-B11 -> -816 | G12: =IFERROR(F12/B11,"") -> -0.0011948306 | H12: 821 | I12: 725 | J12: =B12/I12 -> 940.86345 | K12: =B12/$B$5*100 -> 106.05885
A13: 2024 | B13: 686708 | C13: 445369 | D13: 241339 | E13: =D13/B13 -> 0.35144341 | F13: =B13-B12 -> 4582 | G13: =IFERROR(F13/B12,"") -> 0.0067172341 | H13: 821 | I13: 726 | J13: =B13/I13 -> 945.87879 | K13: =B13/$B$5*100 -> 106.77128
A14: 2025 | B14: 695617 | C14: 454062 | D14: 241555 | E14: =D14/B14 -> 0.34725287 | F14: =B14-B13 -> 8909 | G14: =IFERROR(F14/B13,"") -> 0.012973491 | H14: 812 | I14: 721 | J14: =B14/I14 -> 964.79473 | K14: =B14/$B$5*100 -> 108.15647

Sheet 02_Age_Gender
A1: Players by age band and gender, 2016–2025
A2: Source: S1 (ten DGV yearbooks)
A4: Age band | B4: 2016 | E4: 2017 | H4: 2018 | K4: 2019 | N4: 2020 | Q4: 2021 | T4: 2022 | W4: 2023 | Z4: 2024 | AC4: 2025
A5: Age band | B5: Male | C5: Female | D5: Total | E5: Male | F5: Female | G5: Total | H5: Male | I5: Female | J5: Total | K5: Male | L5: Female | M5: Total | N5: Male | O5: Female | P5: Total | Q5: Male | R5: Female | S5: Total | T5: Male | U5: Female | V5: Total | W5: Male | X5: Female | Y5: Total | Z5: Male | AA5: Female | AB5: Total | AC5: Male | AD5: Female | AE5: Total
A6: Up to 6 | B6: 1170 | C6: 703 | D6: =B6+C6 -> 1873 | E6: 1112 | F6: 670 | G6: =E6+F6 -> 1782 | H6: 1122 | I6: 701 | J6: =H6+I6 -> 1823 | K6: 1058 | L6: 726 | M6: =K6+L6 -> 1784 | N6: 1186 | O6: 754 | P6: =N6+O6 -> 1940 | Q6: 1310 | R6: 861 | S6: =Q6+R6 -> 2171 | T6: 1326 | U6: 886 | V6: =T6+U6 -> 2212 | W6: 1265 | X6: 865 | Y6: =W6+X6 -> 2130 | Z6: 1334 | AA6: 855 | AB6: =Z6+AA6 -> 2189 | AC6: 1347 | AD6: 824 | AE6: =AC6+AD6 -> 2171
A7: 7 to 14 | B7: 16114 | C7: 8202 | D7: =B7+C7 -> 24316 | E7: 15727 | F7: 7994 | G7: =E7+F7 -> 23721 | H7: 15133 | I7: 7887 | J7: =H7+I7 -> 23020 | K7: 14782 | L7: 7608 | M7: =K7+L7 -> 22390 | N7: 14729 | O7: 7726 | P7: =N7+O7 -> 22455 | Q7: 15438 | R7: 8137 | S7: =Q7+R7 -> 23575 | T7: 15302 | U7: 8228 | V7: =T7+U7 -> 23530 | W7: 14582 | X7: 7791 | Y7: =W7+X7 -> 22373 | Z7: 14137 | AA7: 7655 | AB7: =Z7+AA7 -> 21792 | AC7: 14268 | AD7: 7472 | AE7: =AC7+AD7 -> 21740
A8: 15 to 18 | B8: 12578 | C8: 5186 | D8: =B8+C8 -> 17764 | E8: 12093 | F8: 5077 | G8: =E8+F8 -> 17170 | H8: 11643 | I8: 4919 | J8: =H8+I8 -> 16562 | K8: 11368 | L8: 4797 | M8: =K8+L8 -> 16165 | N8: 11761 | O8: 5056 | P8: =N8+O8 -> 16817 | Q8: 12612 | R8: 5560 | S8: =Q8+R8 -> 18172 | T8: 12769 | U8: 5766 | V8: =T8+U8 -> 18535 | W8: 12676 | X8: 5680 | Y8: =W8+X8 -> 18356 | Z8: 12704 | AA8: 5562 | AB8: =Z8+AA8 -> 18266 | AC8: 13350 | AD8: 5537 | AE8: =AC8+AD8 -> 18887
A9: 19 to 20 | B9: 5353 | C9: 2024 | D9: =B9+C9 -> 7377 | E9: 5254 | F9: 2033 | G9: =E9+F9 -> 7287 | H9: 5118 | I9: 1982 | J9: =H9+I9 -> 7100 | K9: 5062 | L9: 2043 | M9: =K9+L9 -> 7105 | N9: 5371 | O9: 2048 | P9: =N9+O9 -> 7419 | Q9: 5744 | R9: 2171 | S9: =Q9+R9 -> 7915 | T9: 6136 | U9: 2259 | V9: =T9+U9 -> 8395 | W9: 6372 | X9: 2338 | Y9: =W9+X9 -> 8710 | Z9: 6595 | AA9: 2478 | AB9: =Z9+AA9 -> 9073 | AC9: 7024 | AD9: 2498 | AE9: =AC9+AD9 -> 9522
A10: 21 to 26 | B10: 14879 | C10: 5157 | D10: =B10+C10 -> 20036 | E10: 14983 | F10: 5171 | G10: =E10+F10 -> 20154 | H10: 15074 | I10: 5298 | J10: =H10+I10 -> 20372 | K10: 15274 | L10: 5377 | M10: =K10+L10 -> 20651 | N10: 16396 | O10: 5888 | P10: =N10+O10 -> 22284 | Q10: 18583 | R10: 6818 | S10: =Q10+R10 -> 25401 | T10: 19744 | U10: 7169 | V10: =T10+U10 -> 26913 | W10: 21136 | X10: 7410 | Y10: =W10+X10 -> 28546 | Z10: 22933 | AA10: 7498 | AB10: =Z10+AA10 -> 30431 | AC10: 24839 | AD10: 8060 | AE10: =AC10+AD10 -> 32899
A11: 27 to 35 | B11: 25206 | C11: 9655 | D11: =B11+C11 -> 34861 | E11: 25200 | F11: 9200 | G11: =E11+F11 -> 34400 | H11: 24879 | I11: 8877 | J11: =H11+I11 -> 33756 | K11: 25299 | L11: 8604 | M11: =K11+L11 -> 33903 | N11: 27102 | O11: 8883 | P11: =N11+O11 -> 35985 | Q11: 29800 | R11: 9674 | S11: =Q11+R11 -> 39474 | T11: 32083 | U11: 10272 | V11: =T11+U11 -> 42355 | W11: 33711 | X11: 10598 | Y11: =W11+X11 -> 44309 | Z11: 36261 | AA11: 11216 | AB11: =Z11+AA11 -> 47477 | AC11: 39369 | AD11: 12016 | AE11: =AC11+AD11 -> 51385
A12: 36 to 40 | B12: 19393 | C12: 8615 | D12: =B12+C12 -> 28008 | E12: 18863 | F12: 8061 | G12: =E12+F12 -> 26924 | H12: 18255 | I12: 7540 | J12: =H12+I12 -> 25795 | K12: 18036 | L12: 7184 | M12: =K12+L12 -> 25220 | N12: 17853 | O12: 6690 | P12: =N12+O12 -> 24543 | Q12: 18346 | R12: 6586 | S12: =Q12+R12 -> 24932 | T12: 18886 | U12: 6522 | V12: =T12+U12 -> 25408 | W12: 19125 | X12: 6213 | Y12: =W12+X12 -> 25338 | Z12: 20100 | AA12: 6285 | AB12: =Z12+AA12 -> 26385 | AC12: 21606 | AD12: 6399 | AE12: =AC12+AD12 -> 28005
A13: 41 to 50 | B13: 70328 | C13: 39631 | D13: =B13+C13 -> 109959 | E13: 66253 | F13: 36526 | G13: =E13+F13 -> 102779 | H13: 61030 | I13: 33420 | J13: =H13+I13 -> 94450 | K13: 56602 | L13: 30648 | M13: =K13+L13 -> 87250 | N13: 52795 | O13: 28258 | P13: =N13+O13 -> 81053 | Q13: 51990 | R13: 27498 | S13: =Q13+R13 -> 79488 | T13: 50959 | U13: 26350 | V13: =T13+U13 -> 77309 | W13: 49188 | X13: 24641 | Y13: =W13+X13 -> 73829 | Z13: 48359 | AA13: 23329 | AB13: =Z13+AA13 -> 71688 | AC13: 48396 | AD13: 22454 | AE13: =AC13+AD13 -> 70850
A14: 51 to 55 | B14: 48365 | C14: 30258 | D14: =B14+C14 -> 78623 | E14: 50110 | F14: 31392 | G14: =E14+F14 -> 81502 | H14: 51408 | I14: 31559 | J14: =H14+I14 -> 82967 | K14: 51802 | L14: 31800 | M14: =K14+L14 -> 83602 | N14: 50885 | O14: 31288 | P14: =N14+O14 -> 82173 | Q14: 49901 | R14: 30978 | S14: =Q14+R14 -> 80879 | T14: 48560 | U14: 30061 | V14: =T14+U14 -> 78621 | W14: 44944 | X14: 27721 | Y14: =W14+X14 -> 72665 | Z14: 40824 | AA14: 25139 | AB14: =Z14+AA14 -> 65963 | AC14: 37439 | AD14: 22880 | AE14: =AC14+AD14 -> 60319
A15: 56 to 60 | B15: 39987 | C15: 27707 | D15: =B15+C15 -> 67694 | E15: 42102 | F15: 28446 | G15: =E15+F15 -> 70548 | H15: 43992 | I15: 29294 | J15: =H15+I15 -> 73286 | K15: 46969 | L15: 30685 | M15: =K15+L15 -> 77654 | N15: 49696 | O15: 31963 | P15: =N15+O15 -> 81659 | Q15: 53246 | R15: 33615 | S15: =Q15+R15 -> 86861 | T15: 55916 | U15: 35419 | V15: =T15+U15 -> 91335 | W15: 57646 | X15: 36313 | Y15: =W15+X15 -> 93959 | Z15: 58289 | AA15: 36450 | AB15: =Z15+AA15 -> 94739 | AC15: 57318 | AD15: 36368 | AE15: =AC15+AD15 -> 93686
A16: 61 and over | B16: 153178 | C16: 99469 | D16: =B16+C16 -> 252647 | E16: 157263 | F16: 101413 | G16: =E16+F16 -> 258676 | H16: 160449 | I16: 102660 | J16: =H16+I16 -> 263109 | K16: 162953 | L16: 104000 | M16: =K16+L16 -> 266953 | N16: 168242 | O16: 106847 | P16: =N16+O16 -> 275089 | Q16: 174848 | R16: 110267 | S16: =Q16+R16 -> 285115 | T16: 176788 | U16: 111541 | V16: =T16+U16 -> 288329 | W16: 179148 | X16: 112763 | Y16: =W16+X16 -> 291911 | Z16: 183833 | AA16: 114872 | AB16: =Z16+AA16 -> 298705 | AC16: 189106 | AD16: 117047 | AE16: =AC16+AD16 -> 306153
A17: Total | B17: =SUM(B6:B16) -> 406551 | C17: =SUM(C6:C16) -> 236607 | D17: =SUM(D6:D16) -> 643158 | E17: =SUM(E6:E16) -> 408960 | F17: =SUM(F6:F16) -> 235983 | G17: =SUM(G6:G16) -> 644943 | H17: =SUM(H6:H16) -> 408103 | I17: =SUM(I6:I16) -> 234137 | ... AE17: =SUM(AE6:AE16) -> 695617

Sheet 03_States
A1: State golf associations: participation, growth and market penetration
A2: Players 30 Sep; facilities 31 Dec 2025; population Destatis 31 Dec 2024. Sources: S1, S6
F3: 2025
A4: State golf association | B4: Players 2025 | C4: Players 2016 | D4: Change (abs.) | E4: Change (%) | F4: Male 2025 | G4: Female 2025 | H4: Female share | I4: Under 19 | J4: Aged 61+ | K4: Population | L4: Players per 1,000 pop. | M4: Players per facility | N4: Facilities 2025
A5: Baden-Württemberg | B5: 76079 | C5: 73638 | D5: =B5-C5 -> 2441 | E5: =IFERROR(D5/C5,"") -> 0.033148646 | F5: 48708 | G5: 27371 | H5: =G5/B5 -> 0.35977076 | I5: 5892 | J5: 36879 | K5: 11245898 | L5: =B5/K5*1000 -> 6.7650445 | M5: =IFERROR(B5/N5,"") -> 854.82022 | N5: 89
A6: Bavaria | B6: 144501 | C6: 138837 | D6: =B6-C6 -> 5664 | E6: =IFERROR(D6/C6,"") -> 0.040796041 | F6: 92486 | G6: 52015 | H6: =G6/B6 -> 0.35996291 | I6: 9557 | J6: 63445 | K6: 13248928 | L6: =B6/K6*1000 -> 10.906618 | M6: =IFERROR(B6/N6,"") -> 845.03509 | N6: 171
A7: Berlin/Brandenburg Metropolitan Region | B7: 27777 | C7: 24022 | D7: =B7-C7 -> 3755 | E7: =IFERROR(D7/C7,"") -> 0.15631504 | F7: 18775 | G7: 9002 | H7: =G7/B7 -> 0.32408107 | I7: 1774 | J7: 11155 | K7: 6242012 | L7: =B7/K7*1000 -> 4.4500075 | M7: =IFERROR(B7/N7,"") -> 1461.9474 | N7: 19
A8: Hamburg | B8: 22099 | C8: 21615 | D8: =B8-C8 -> 484 | E8: =IFERROR(D8/C8,"") -> 0.022391858 | F8: 13936 | G8: 8163 | H8: =G8/B8 -> 0.36938323 | I8: 2351 | J8: 9527 | K8: 1862565 | L8: =B8/K8*1000 -> 11.864821 | M8: =IFERROR(B8/N8,"") -> 1163.1053 | N8: 19
A9: Hesse | B9: 49741 | C9: 48284 | D9: =B9-C9 -> 1457 | E9: =IFERROR(D9/C9,"") -> 0.030175628 | F9: 32266 | G9: 17475 | H9: =G9/B9 -> 0.35131984 | I9: 3830 | J9: 22652 | K9: 6280793 | L9: =B9/K9*1000 -> 7.9195414 | M9: =IFERROR(B9/N9,"") -> 938.50943 | N9: 53
A10: Mecklenburg-Vorpommern | B10: 18752 | C10: 17152 | D10: =B10-C10 -> 1600 | E10: =IFERROR(D10/C10,"") -> 0.093283582 | F10: 12251 | G10: 6501 | H10: =G10/B10 -> 0.34668302 | I10: 557 | J10: 7183 | K10: 1573597 | L10: =B10/K10*1000 -> 11.916647 | M10: =IFERROR(B10/N10,"") -> 1103.0588 | N10: 17
A11: Lower Saxony | B11: 78772 | C11: 72383 | D11: =B11-C11 -> 6389 | E11: =IFERROR(D11/C11,"") -> 0.088266582 | F11: 52184 | G11: 26588 | H11: =G11/B11 -> 0.3375311 | I11: 4131 | J11: 35353 | K11: 8709370 | L11: =B11/K11*1000 -> 9.0445118 | M11: =IFERROR(B11/N11,"") -> 1009.8974 | N11: 78
A12: North Rhine-Westphalia | B12: 144750 | C12: 134637 | D12: =B12-C12 -> 10113 | E12: =IFERROR(D12/C12,"") -> 0.075113082 | F12: 94837 | G12: 49913 | H12: =G12/B12 -> 0.34482211 | I12: 8113 | J12: 67040 | K12: 18034454 | L12: =B12/K12*1000 -> 8.0263034 | M12: =IFERROR(B12/N12,"") -> 921.97452 | N12: 157
A13: Rhineland-Palatinate | B13: 30113 | C13: 28298 | D13: =B13-C13 -> 1815 | E13: =IFERROR(D13/C13,"") -> 0.064138808 | F13: 19803 | G13: 10310 | H13: =G13/B13 -> 0.34237705 | I13: 1877 | J13: 14337 | K13: 5141710 | L13: =B13/K13*1000 -> 5.8566119 | M13: =IFERROR(B13/N13,"") -> 772.12821 | N13: 39
A14: Saxony-Anhalt | B14: 2168 | C14: 1601 | D14: =B14-C14 -> 567 | E14: =IFERROR(D14/C14,"") -> 0.35415365 | F14: 1113 | G14: 1055 | H14: =G14/B14 -> 0.48662362 | I14: 172 | J14: 679 | K14: 2135597 | L14: =B14/K14*1000 -> 1.0151728 | M14: =IFERROR(B14/N14,"") -> 433.6 | N14: 5
A15: Saxony | B15: 13696 | C15: 11727 | D15: =B15-C15 -> 1969 | E15: =IFERROR(D15/C15,"") -> 0.16790313 | F15: 9222 | G15: 4474 | H15: =G15/B15 -> 0.32666472 | I15: 835 | J15: 4784 | K15: 6142699 | L15: =B15/K15*1000 -> 2.2296388 | M15: =IFERROR(B15/N15,"") -> 652.19048 | N15: 21
A16: Schleswig-Holstein | B16: 54471 | C16: 48255 | D16: =B16-C16 -> 6216 | E16: =IFERROR(D16/C16,"") -> 0.12881567 | F16: 35144 | G16: 19327 | H16: =G16/B16 -> 0.35481265 | I16: 3399 | J16: 24189 | K16: 2959517 | L16: =B16/K16*1000 -> 18.405368 | M16: =IFERROR(B16/N16,"") -> 1027.7547 | N16: 53
A17: VcG (non-club members, nationwide) | B17: 32698 | C17: 22709 | D17: =B17-C17 -> 9989 | E17: =IFERROR(D17/C17,"") -> 0.43986966 | F17: 23337 | G17: 9361 | H17: =G17/B17 -> 0.28628662 | I17: 310 | J17: 8930 | K17: n/a | L17: n/a | M17: n/a | N17: n/a
A18: Total | B18: =SUM(B5:B17) -> 695617 | C18: =SUM(C5:C17) -> 643158 | D18: =SUM(D5:D17) -> 52459 | E18: =D18/C18 -> 0.081564717 | F18: =SUM(F5:F17) -> 454062 | G18: =SUM(G5:G17) -> 241555 | H18: =G18/B18 -> 0.34725287 | I18: =SUM(I5:I17) -> 42798 | J18: =SUM(J5:J17) -> 306153
A20: VcG is a nationwide membership category, not a region; it is excluded from all penetration metrics.
A22: Geographic labelling note — map labels are narrower than the reporting units.
A23: Column A was converted to Excel Geography data types to drive the regional map. Excel resolves each label to a single federal state, but three associations that span two federal states resolve to the larger state only:
A24: Lower Saxony = Niedersachsen AND Bremen · Rhineland-Palatinate = Rheinland-Pfalz AND Saarland · Saxony = Sachsen AND Thüringen.
A25: All figures and population denominators in those rows cover the full combined territory — the Lower Saxony row uses 8,709,370 residents (Niedersachsen 8,004,489 + Bremen 704,881). Membership is not published below association level in any source, so no finer split is possible. Read the map as associations plotted on their largest state, not as federal states.
A28: Map helper table — one row per federal state
A29: Convert column A to Excel Geography data types, then build the regional map from column A and column E. Each federal state carries the rate of the DGV association that serves it, so all sixteen states are shaded. Four associations cover two states each (column B names them).
A30: Federal state | B30: DGV state association | C30: Players 2025 | D30: Population | E30: Players per 1,000 pop. | F30: Untapped potential to national average | G30: Change 2016–2025 (%)
A31: Baden-Württemberg | B31: Baden-Württemberg | C31: =B5 -> 76079 | D31: =K5 -> 11245898 | E31: =L5 -> 6.7650445 | F31: =L5 -> 6.7650445 | G31: =E5 -> 0.033148646
A32: Bavaria | B32: Bayern | C32: =B6 -> 144501 | D32: =K6 -> 13248928 | E32: =L6 -> 10.906618 | F32: =L6 -> 10.906618 | G32: =E6 -> 0.040796041
A33: Berlin | B33: Berlin/Brandenburg | C33: =B7 -> 27777 | D33: =K7 -> 6242012 | E33: =L7 -> 4.4500075 | F33: =L7 -> 4.4500075 | G33: =E7 -> 0.15631504
A34: Brandenburg | B34: Berlin/Brandenburg | C34: =B7 -> 27777 | D34: =K7 -> 6242012 | E34: =L7 -> 4.4500075 | F34: =L7 -> 4.4500075 | G34: =E7 -> 0.15631504
A35: Bremen | B35: Niedersachsen/Bremen | C35: =B11 -> 78772 | D35: =K11 -> 8709370 | E35: =L11 -> 9.0445118 | F35: =L11 -> 9.0445118 | G35: =E11 -> 0.088266582
A36: Hamburg | B36: Hamburg | C36: =B8 -> 22099 | D36: =K8 -> 1862565 | E36: =L8 -> 11.864821 | F36: =L8 -> 11.864821 | G36: =E8 -> 0.022391858
A37: Hesse | B37: Hessen | C37: =B9 -> 49741 | D37: =K9 -> 6280793 | E37: =L9 -> 7.9195414 | F37: =L9 -> 7.9195414 | G37: =E9 -> 0.030175628
A38: Lower Saxony | B38: Niedersachsen/Bremen | C38: =B11 -> 78772 | D38: =K11 -> 8709370 | E38: =L11 -> 9.0445118 | F38: =L11 -> 9.0445118 | G38: =E11 -> 0.088266582
A39: Mecklenburg-Vorpommern | B39: Mecklenburg-Vorpommern | C39: =B10 -> 18752 | D39: =K10 -> 1573597 | E39: =L10 -> 11.916647 | F39: =L10 -> 11.916647 | G39: =E10 -> 0.093283582
A40: North Rhine-Westphalia | B40: Nordrhein-Westfalen | C40: =B12 -> 144750 | D40: =K12 -> 18034454 | E40: =L12 -> 8.0263034 | F40: =L12 -> 8.0263034 | G40: =E12 -> 0.075113082
A41: Rhineland-Palatinate | B41: Rheinland-Pfalz/Saarland | C41: =B13 -> 30113 | D41: =K13 -> 5141710 | E41: =L13 -> 5.8566119 | F41: =L13 -> 5.8566119 | G41: =E13 -> 0.064138808
A42: Saarland | B42: Rheinland-Pfalz/Saarland | C42: =B13 -> 30113 | D42: =K13 -> 5141710 | E42: =L13 -> 5.8566119 | F42: =L13 -> 5.8566119 | G42: =E13 -> 0.064138808
A43: Saxony | B43: Sachsen/Thüringen | C43: =B15 -> 13696 | D43: =K15 -> 6142699 | E43: =L15 -> 2.2296388 | F43: =L15 -> 2.2296388 | G43: =E15 -> 0.16790313
A44: Saxony-Anhalt | B44: Sachsen-Anhalt | C44: =B14 -> 2168 | D44: =K14 -> 2135597 | E44: =L14 -> 1.0151728 | F44: =L14 -> 1.0151728 | G44: =E14 -> 0.35415365
...

Sheet 04_Funnel
A1: From awareness to membership: the participation funnel, 2019–2025
A2: Allensbach AWA via Statista, in millions, base German-speaking population aged 14+ (S3); DGV membership from S1
A4: Stage (millions of people) | B4: 2019 | C4: 2020 | D4: 2021 | E4: 2022 | F4: 2023 | G4: 2024 | H4: 2025 | I4: Change 2019–25
A5: Aware of golf | B5: 67.62 | C5: 67.85 | D5: 68 | E5: 68.08 | F5: 67.85 | G5: 68.51 | H5: 69.13 | I5: =IFERROR(H5/B5-1,"") -> 0.022330671
A6: Interested (strongly or somewhat) | B6: 6.7 | C6: 6.56 | D6: 6.11 | E6: 6.01 | F6: 6.16 | G6: 6.45 | H6: 6.87 | I6: =IFERROR(H6/B6-1,"") -> 0.025373134
A7: of which strongly interested | B7: 1.47 | C7: 1.55 | D7: 1.46 | E7: 1.35 | F7: 1.32 | G7: 1.45 | H7: 1.62 | I7: =IFERROR(H7/B7-1,"") -> 0.10204082
A8: Play golf (often or occasionally) | B8: 2.89 | C8: 3.04 | D8: 3.14 | E8: 3.12 | F8: 3.27 | G8: 3.44 | H8: 3.38 | I8: =IFERROR(H8/B8-1,"") -> 0.16955017
A9: of which play often | B9: 0.75 | C9: 0.81 | D9: 0.87 | E9: 0.87 | F9: 0.9 | G9: 0.91 | H9: 0.9 | I9: =IFERROR(H9/B9-1,"") -> 0.2
A10: DGV-registered members | B10: 0.643 | C10: 0.651 | D10: 0.674 | E10: 0.683 | F10: 0.682 | G10: 0.687 | H10: 0.696 | I10: =IFERROR(H10/B10-1,"") -> 0.082426128
A13: Conversion ratios, 2025
A14: Ratio | B14: Value
A15: Interested people per registered member | B15: =H6/H10 -> 9.8706897
A16: Occasional or frequent players per registered member | B16: =H8/H10 -> 4.8563218
A17: Registered members as a share of interested people | B17: =H10/H6 -> 0.10131004
A18: Registered members as a share of people who play | B18: =H10/H8 -> 0.20591716
A19: Interested but not playing (millions) | B19: =H6-H8 -> 3.49
A20: Playing but not registered (millions) | B20: =H8-H10 -> 2.684
A22: Note: the Allensbach survey base (population aged 14+) and the DGV administrative count are not identical populations. The ratios indicate magnitude, not exact rates.
A24: Ready for Excel's native Funnel chart
A25: Select A26:B31, then Insert > Insert Waterfall, Funnel, Stock, Surface or Radar Chart > Funnel.
A26: Funnel stage | B26: People (millions)
A27: Aware of golf | B27: =H5 -> 69.13
A28: Interested in golf | B28: =H6 -> 6.87
A29: Play golf at all | B29: =H8 -> 3.38
A30: Play golf often | B30: =H9 -> 0.9
A31: DGV-registered member | B31: =H10 -> 0.696
A33: Stage sizes in millions of people
A34: Grey = interested, orange = people who play, blue = DGV members. Millions of people.
A35: Stage | B35: 2019 | C35: 2020 | D35: 2021 | E35: 2022 | F35: 2023 | G35: 2024 | H35: 2025
A36: Interested in golf | B36: =B6 -> 6.7 | C36: =C6 -> 6.56 | D36: =D6 -> 6.11 | E36: =E6 -> 6.01 | F36: =F6 -> 6.16 | G36: =G6 -> 6.45 | H36: =H6 -> 6.87
A37: Play golf at all | B37: =B8 -> 2.89 | C37: =C8 -> 3.04 | D37: =D8 -> 3.14 | E37: =E8 -> 3.12 | F37: =F8 -> 3.27 | G37: =G8 -> 3.44 | H37: =H8 -> 3.38
A38: DGV-registered members | B38: =B10 -> 0.643 | C38: =C10 -> 0.651 | D38: =D10 -> 0.674 | E38: =E10 -> 0.683 | F38: =F10 -> 0.682 | G38: =G10 -> 0.687 | H38: =H10 -> 0.696
A39: Year | B39: 2019 | C39: 2020 | D39: 2021 | E39: 2022 | F39: 2023 | G39: 2024 | H39: 2025
A40: Playing without a membership | B40: =B8-B10 -> 2.247 | C40: =C8-C10 -> 2.389 | D40: =D8-D10 -> 2.466 | E40: =E8-E10 -> 2.437 | F40: =F8-F10 -> 2.588 | G40: =G8-G10 -> 2.753 | H40: =H8-H10 -> 2.684
A42: Golfers who play but hold no DGV membership: 2.25m in 2019, 2.68m in 2025 — an increase of 437,000 in six years.

Sheet 05_Europe
A1: European benchmark: registered golfers, penetration and female share, 2024
A2: The R&A, Global Golf Participation 2024 (S5). Adults are split by gender; juniors counted separately.
A4: Country | B4: Population | C4: Registered golfers | D4: Adult male | E4: Adult female | F4: Juniors | G4: Courses | H4: Per 1,000 population | I4: Adult female share | J4: Golfers per course | K4: Population per course
A5: Iceland | B5: 393349 | C5: 26349 | D5: 14924 | E5: 7905 | F5: 3520 | G5: 64 | H5: =C5/B5*1000 -> 66.986315 | I5: =E5/(D5+E5) -> 0.3462701 | J5: =C5/G5 -> 411.70312 | K5: =B5/G5 -> 6146.0781
A6: Sweden | B6: 10536632 | C6: 561677 | D6: 361387 | E6: 118782 | F6: 81508 | G6: 680 | H6: =C6/B6*1000 -> 53.307072 | I6: =E6/(D6+E6) -> 0.2473754 | J6: =C6/G6 -> 825.99559 | K6: =B6/G6 -> 15495.047
A7: Scotland | B7: 5490100 | C7: 210278 | D7: 162488 | E7: 21957 | F7: 25833 | G7: 550 | H7: =C7/B7*1000 -> 38.301306 | I7: =E7/(D7+E7) -> 0.11904362 | J7: =C7/G7 -> 382.32364 | K7: =B7/G7 -> 9982
A8: Ireland | B8: 7228000 | C8: 225363 | D8: 158548 | E8: 39637 | F8: 27178 | G8: 377 | H8: =C8/B8*1000 -> 31.179164 | I8: =E8/(D8+E8) -> 0.2 | J8: =C8/G8 -> 597.77984 | K8: =B8/G8 -> 19172.414
A9: Finland | B9: 5583911 | C9: 156315 | D9: 98554 | E9: 37661 | F9: 20100 | G9: 161 | H9: =C9/B9*1000 -> 27.99382 | I9: =E9/(D9+E9) -> 0.27648203 | J9: =C9/G9 -> 970.90062 | K9: =B9/G9 -> 34682.677
A10: Denmark | B10: 5946952 | C10: 162957 | D10: 112307 | E10: 43101 | F10: 7549 | G10: 192 | H10: =C10/B10*1000 -> 27.401768 | I10: =E10/(D10+E10) -> 0.27734093 | J10: =C10/G10 -> 848.73438 | K10: =B10/G10 -> 30973.708
A11: Norway | B11: 5519594 | C11: 149288 | D11: 101932 | E11: 26461 | F11: 20895 | G11: 174 | H11: =C11/B11*1000 -> 27.046917 | I11: =E11/(D11+E11) -> 0.20609379 | J11: =C11/G11 -> 857.97701 | K11: =B11/G11 -> 31721.805
A12: Netherlands | B12: 17877117 | C12: 446888 | D12: 294049 | E12: 135755 | F12: 17084 | G12: 259 | H12: =C12/B12*1000 -> 24.997767 | I12: =E12/(D12+E12) -> 0.31585327 | J12: =C12/G12 -> 1725.4363 | K12: =B12/G12 -> 69023.618
A13: Wales | B13: 3164400 | C13: 52641 | D13: 42808 | E13: 5297 | F13: 4536 | G13: 149 | H13: =C13/B13*1000 -> 16.635381 | I13: =E13/(D13+E13) -> 0.11011329 | J13: =C13/G13 -> 353.2953 | K13: =B13/G13 -> 21237.584
A14: England | B14: 57690300 | C14: 790728 | D14: 658852 | E14: 85457 | F14: 46419 | G14: 2304 | H14: =C14/B14*1000 -> 13.706429 | I14: =E14/(D14+E14) -> 0.11481387 | J14: =C14/G14 -> 343.19792 | K14: =B14/G14 -> 25039.193
A15: Switzerland | B15: 8888093 | C15: 105109 | D15: 63393 | E15: 35192 | F15: 6524 | G15: 128 | H15: =C15/B15*1000 -> 11.825821 | I15: =E15/(D15+E15) -> 0.35697114 | J15: =C15/G15 -> 821.16406 | K15: =B15/G15 -> 69438.227
A16: Austria | B16: 9131761 | C16: 94926 | D16: 55071 | E16: 33136 | F16: 6719 | G16: 175 | H16: =C16/B16*1000 -> 10.395147 | I16: =E16/(D16+E16) -> 0.3756618 | J16: =C16/G16 -> 542.43429 | K16: =B16/G16 -> 52181.491
... A21: Italy | B21: 58993475 | C21: 94090 | D21: 64611 | E21: 20235 | F21: 9244 | G21: 270 | H21: =C21/B21*1000 -> 1.5949222 | I21: =E21/(D21+E21) -> 0.23849091 | J21: =C21/G21 -> 348.48148 | K21: =B21/G21 -> 218494.35
A22: Europe total | B22: 833390649 | C22: 4716230 | D22: 3225691 | E22: 1069196 | F22: 421343 | G22: 7939 | H22: =C22/B22*1000 -> 5.6590868 | I22: =E22/(D22+E22) -> 0.24894625

Sheet 06_Metrics
A1: Derived metrics
A2: Live formulas into the data sheets — edit the raw data and these follow
A4: A) Growth by age band, 2016 to 2025
A5: Age band | B5: 2016 | C5: 2025 | D5: Change (abs.) | E5: Change (%) | F5: Share of total 2025 | G5: Contribution to net growth
A6: Up to 6 | B6: ='02_Age_Gender'!D6 -> 1873 | C6: ='02_Age_Gender'!AE6 -> 2171 | D6: =C6-B6 -> 298 | E6: =IFERROR(D6/B6,"") -> 0.15910304 | F6: =C6/SUM($C$6:$C$16) -> 0.0031209703 | G6: =D6/SUM($D$6:$D$16) -> 0.0056806268
A7: 7 to 14 | B7: ='02_Age_Gender'!D7 -> 24316 | C7: ='02_Age_Gender'!AE7 -> 21740 | D7: =C7-B7 -> -2576 | E7: =IFERROR(D7/B7,"") -> -0.10593848 | F7: =C7/SUM($C$6:$C$16) -> 0.03125283 | G7: =D7/SUM($D$6:$D$16) -> -0.049105015
A8: 15 to 18 | B8: ='02_Age_Gender'!D8 -> 17764 | C8: ='02_Age_Gender'!AE8 -> 18887 | D8: =C8-B8 -> 1123 | E8: =IFERROR(D8/B8,"") -> 0.063217744 | F8: =C8/SUM($C$6:$C$16) -> 0.027151435 | G8: =D8/SUM($D$6:$D$16) -> 0.021407194
A9: 19 to 20 | B9: ='02_Age_Gender'!D9 -> 7377 | C9: ='02_Age_Gender'!AE9 -> 9522 | D9: =C9-B9 -> 2145 | E9: =IFERROR(D9/B9,"") -> 0.29076861 | F9: =C9/SUM($C$6:$C$16) -> 0.013688567 | G9: =D9/SUM($D$6:$D$16) -> 0.040889075
A10: 21 to 26 | B10: ='02_Age_Gender'!D10 -> 20036 | C10: ='02_Age_Gender'!AE10 -> 32899 | D10: =C10-B10 -> 12863 | E10: =IFERROR(D10/B10,"") -> 0.64199441 | F10: =C10/SUM($C$6:$C$16) -> 0.047294704 | G10: =D10/SUM($D$6:$D$16) -> 0.24520101
A11: 27 to 35 | B11: ='02_Age_Gender'!D11 -> 34861 | C11: ='02_Age_Gender'!AE11 -> 51385 | D11: =C11-B11 -> 16524 | E11: =IFERROR(D11/B11,"") -> 0.47399673 | F11: =C11/SUM($C$6:$C$16) -> 0.073869673 | G11: =D11/SUM($D$6:$D$16) -> 0.31498885
A12: 36 to 40 | B12: ='02_Age_Gender'!D12 -> 28008 | C12: ='02_Age_Gender'!AE12 -> 28005 | D12: =C12-B12 -> -3 | E12: =IFERROR(D12/B12,"") -> -0.00010711225 | F12: =C12/SUM($C$6:$C$16) -> 0.040259223 | G12: =D12/SUM($D$6:$D$16) -> -5.7187518e-05
A13: 41 to 50 | B13: ='02_Age_Gender'!D13 -> 109959 | C13: ='02_Age_Gender'!AE13 -> 70850 | D13: =C13-B13 -> -39109 | E13: =IFERROR(D13/B13,"") -> -0.35566893 | F13: =C13/SUM($C$6:$C$16) -> 0.10185202 | G13: =D13/SUM($D$6:$D$16) -> -0.74551555
A14: 51 to 55 | B14: ='02_Age_Gender'!D14 -> 78623 | C14: ='02_Age_Gender'!AE14 -> 60319 | D14: =C14-B14 -> -18304 | E14: =IFERROR(D14/B14,"") -> -0.23280719 | F14: =C14/SUM($C$6:$C$16) -> 0.086712947 | G14: =D14/SUM($D$6:$D$16) -> -0.34892011
A15: 56 to 60 | B15: ='02_Age_Gender'!D15 -> 67694 | C15: ='02_Age_Gender'!AE15 -> 93686 | D15: =C15-B15 -> 25992 | E15: =IFERROR(D15/B15,"") -> 0.38396313 | F15: =C15/SUM($C$6:$C$16) -> 0.13468043 | G15: =D15/SUM($D$6:$D$16) -> 0.49547265
A16: 61 and over | B16: ='02_Age_Gender'!D16 -> 252647 | C16: ='02_Age_Gender'!AE16 -> 306153 | D16: =C16-B16 -> 53506 | E16: =IFERROR(D16/B16,"") -> 0.21178166 | F16: =C16/SUM($C$6:$C$16) -> 0.44011719 | G16: =D16/SUM($D$6:$D$16) -> 1.0199584
A19: B) Market penetration by state association (VcG excluded)
A20: State golf association | B20: Players 2025 | C20: Population | D20: Players per 1,000 pop. | E20: Change (%) 2016–25 | F20: Female share | G20: Density rank | H20: vs national average
A21: Schleswig-Holstein | B21: ='03_States'!B16 -> 54471 | C21: ='03_States'!K16 -> 2959517 | D21: =B21/C21*1000 -> 18.405368 | E21: ='03_States'!E16 -> 0.12881567 | F21: ='03_States'!H16 -> 0.35481265 | G21: =RANK(D21,$D$21:$D$32) -> 1 | H21: =D21-'01_Timeseries'!$B$14/83577140*1000 -> 10.082315
A22: Mecklenburg-Vorpommern | B22: ='03_States'!B10 -> 18752 | C22: ='03_States'!K10 -> 1573597 | D22: =B22/C22*1000 -> 11.916647 | E22: ='03_States'!E10 -> 0.093283582 | F22: ='03_States'!H10 -> 0.34668302 | G22: =RANK(D22,$D$21:$D$32) -> 2 | H22: =D22-'01_Timeseries'!$B$14/83577140*1000 -> 3.5935936
A23: Hamburg | B23: ='03_States'!B8 -> 22099 | C23: ='03_States'!K8 -> 1862565 | D23: =B23/C23*1000 -> 11.864821 | E23: ='03_States'!E8 -> 0.022391858 | F23: ='03_States'!H8 -> 0.36938323 | G23: =RANK(D23,$D$21:$D$32) -> 3 | H23: =D23-'01_Timeseries'!$B$14/83577140*1000 -> 3.5417674
A24: Bayern | B24: ='03_States'!B6 -> 144501 | C24: ='03_States'!K6 -> 13248928 | D24: =B24/C24*1000 -> 10.906618 | E24: ='03_States'!E6 -> 0.040796041 | F24: ='03_States'!H6 -> 0.35996291 | G24: =RANK(D24,$D$21:$D$32) -> 4 | H24: =D24-'01_Timeseries'!$B$14/83577140*1000 -> 2.5835648
A25: Niedersachsen/Bremen | B25: ='03_States'!B11 -> 78772 | C25: ='03_States'!K11 -> 8709370 | D25: =B25/C25*1000 -> 9.0445118 | E25: ='03_States'!E11 -> 0.088266582 | F25: ='03_States'!H11 -> 0.3375311 | G25: =RANK(D25,$D$21:$D$32) -> 5 | H25: =D25-'01_Timeseries'!$B$14/83577140*1000 -> 0.72145842
A26: Nordrhein-Westfalen | B26: ='03_States'!B12 -> 144750 | C26: ='03_States'!K12 -> 18034454 | D26: =B26/C26*1000 -> 8.0263034 | E26: ='03_States'!E12 -> 0.075113082 | F26: ='03_States'!H12 -> 0.34482211 | G26: =RANK(D26,$D$21:$D$32) -> 6 | H26: =D26-'01_Timeseries'!$B$14/83577140*1000 -> -0.29674998
A27: Hessen | B27: ='03_States'!B9 -> 49741 | C27: ='03_States'!K9 -> 6280793 | D27: =B27/C27*1000 -> 7.9195414 | E27: ='03_States'!E9 -> 0.030175628 | F27: ='03_States'!H9 -> 0.35131984 | G27: =RANK(D27,$D$21:$D$32) -> 7 | H27: =D27-'01_Timeseries'!$B$14/83577140*1000 -> -0.40351204
A28: Baden-Württemberg | B28: ='03_States'!B5 -> 76079 | C28: ='03_States'!K5 -> 11245898 | D28: =B28/C28*1000 -> 6.7650445 | E28: ='03_States'!E5 -> 0.033148646 | F28: ='03_States'!H5 -> 0.35977076 | G28: =RANK(D28,$D$21:$D$32) -> 8 | H28: =D28-'01_Timeseries'!$B$14/83577140*1000 -> -1.5580089
A29: Rheinland-Pfalz/Saarland | B29: ='03_States'!B13 -> 30113 | C29: ='03_States'!K13 -> 5141710 | D29: =B29/C29*1000 -> 5.8566119 | E29: ='03_States'!E13 -> 0.064138808 | F29: ='03_States'!H13 -> 0.34237705 | G29: =RANK(D29,$D$21:$D$32) -> 9 | H29: =D29-'01_Timeseries'!$B$14/83577140*1000 -> -2.4664415
A30: Berlin/Brandenburg | B30: ='03_States'!B7 -> 27777 | C30: ='03_States'!K7 -> 6242012 | D30: =B30/C30*1000 -> 4.4500075 | E30: ='03_States'!E7 -> 0.15631504 | F30: ='03_States'!H7 -> 0.32408107 | G30: =RANK(D30,$D$21:$D$32) -> 10 | H30: =D30-'01_Timeseries'!$B$14/83577140*1000 -> -3.8730459
A31: Sachsen/Thüringen | B31: ='03_States'!B15 -> 13696 | C31: ='03_States'!K15 -> 6142699 | D31: =B31/C31*1000 -> 2.2296388 | E31: ='03_States'!E15 -> 0.16790313 | F31: ='03_States'!H15 -> 0.32666472 | G31: =RANK(D31,$D$21:$D$32) -> 11 | H31: =D31-'01_Timeseries'!$B$14/83577140*1000 -> -6.0934146
A32: Sachsen-Anhalt | B32: ='03_States'!B14 -> 2168 | C32: ='03_States'!K14 -> 2135597 | D32: =B32/C32*1000 -> 1.0151728 | E32: ='03_States'!E14 -> 0.35415365 | F32: ='03_States'!H14 -> 0.48662362 | G32: =RANK(D32,$D$21:$D$32) -> 12 | H32: =D32-'01_Timeseries'!$B$14/83577140*1000 -> -7.3078806
A35: C) Ready for Excel's native Waterfall chart — net change by age band, 2016 to 2025
A36: Select A38:B49, then Insert > Insert Waterfall, Funnel, Stock, Surface or Radar Chart > Waterfall. Right-click the Total bar > Set as Total.
A37: Age band | B37: Net change 2016–2025
A38: Up to 6 | B38: =D6 -> 298
A39: 7 to 14 | B39: =D7 -> -2576
A40: 15 to 18 | B40: =D8 -> 1123
A41: 19 to 20 | B41: =D9 -> 2145
A42: 21 to 26 | B42: =D10 -> 12863
A43: 27 to 35 | B43: =D11 -> 16524
A44: 36 to 40 | B44: =D12 -> -3
A45: 41 to 50 | B45: =D13 -> -39109
...

Sheet 20_Dashboard
B2: GROWING GOLF IN GERMANY - Participation Dashboard 2016-2025
B4: Primary audience: DGV executive board · Secondary: the twelve state golf associations | Players as at 30 Sep 2025, facilities 31 Dec 2025 | Sources: DGV; Allensbach/AWA; The R&A; Destatis
B5: Compare 2025 with: | C5: 2024
B6: PLAYERS 2025 | D6: ="GROWTH vs "&'06_Metrics'!B68 -> GROWTH vs 2024 | F6: FEMALE SHARE 2025 | H6: AGED 61+ | J6: ="UNDER 19 vs "&'06_Metrics'!B68 -> UNDER 19 vs 2024
B7: ='06_Metrics'!B52 -> 695617 | D7: ='06_Metrics'!B74 -> 0.012973491 | F7: ='06_Metrics'!B56 -> 0.34725287 | H7: ='06_Metrics'!B58 -> 0.44011719 | J7: ='06_Metrics'!B77 -> 0.013042346
B9: ="Compared with "&'06_Metrics'!B68&": "&TEXT('06_Metrics'!B73,"+#,##0;-#,##0")&" members "&"("&TEXT('06_Metrics'!B74,"+0.0%;-0.0%")&")"&" · female share "&TEXT('06_Metrics'!B75,"+0.0;-0.0")&" pp"&" · aged 61+ "&TEXT('06_Metrics'!B76,"+0.0;-0.0")&" pp"&" · under 19 "&TEXT('06_Metrics'!B77,"+0.0%;-0.0%") -> Compared with 2024: +8909,0 members (+01%) · female share -00 pp · aged 61+ +01 pp · under 19 +01%
B11: 1 Golf memberships 2016–2025: a record total built on a narrow base | H11: 2 The unconverted pool keeps growing: 2.25m in 2019, 2.68m in 2025
B29: 3 The centre of gravity shifts: the 41–60 cohort falls below the over-60s | H29: 4 Where golf loses women: the share halves between childhood and age 40
B47: 5 Domestic headroom: penetration varies eighteenfold (red line = national average, 8.3) | H47: 6 European ceiling: Germany sits far below the northern markets
B65: 7 A coastal pattern, not an east-west one: the three lowest regions are eastern, the three highest lie on the northern coast
B98: Colour encoding: blue #0072B2 = male members and volume measures, orange #E69F00 = female members and the opportunity measure | Sources: Deutscher Golf Verband (2017–2026); Institut für Demoskopie Allensbach / AWA 2025 via Statista; The R&A (2025); Statistisches Bundesamt (2025). Full source list and caveats on sheet 00_README.
