Workbook

Sheet 00_README
A1: ICT702 Task 2 — Growing Golf in Germany
A2: Data sources, definitions and workbook structure
A5: PURPOSE | B5: Data basis for an Excel dashboard supporting the German Golf Federation (DGV) and golf facility operators in decisions aimed at increasing participation in golf.
A6: TARGET AUDIENCE | B6: DGV executive board, state golf associations, golf facility operators.
A7: CENSUS DATE (PLAYERS) | B7: 30 September of each year (DGV-registered memberships).
A8: CENSUS DATE (FACILITIES) | B8: 31 December of each year.
A10: SOURCES
A11: S1 | B11: Deutscher Golf Verband. (2026). DGV-Statistiken 2025 gesamt [DGV statistics 2025, complete]. https://serviceportal.dgv-intranet.de/files/pdf3/26-01-21-01-dgv_zahlen_gesamt_2025.pdf
A12: S2 | B12: Deutscher Golf Verband. (2026). Golf in Deutschland erreicht neue Höchstwerte [Press release]. https://serviceportal.dgv-intranet.de/files/pdf3/26-01-21-01-pm-golferzahlen.pdf
A13: S3 | B13: Deutscher Golf Verband. (2023). DGV-Statistiken 2022 [DGV statistics 2022]. https://serviceportal.dgv-intranet.de/files/pdf3/23-01-18_01_dgv_statistiken-2022.pdf
A14: S4 | B14: Deutscher Golf Verband. (2026). Allgemeine DGV-Statistiken [General DGV statistics, 2016–2025]. https://serviceportal.dgv-intranet.de/marketing-betrieb/markt-daten/allgemeine-statistiken.cfm
A15: S5 | B15: Statistisches Bundesamt. (2025). Bundesländer mit Hauptstädten nach Fläche, Bevölkerung und Bevölkerungsdichte am 31.12.2024 [Federal states by area and population]. https://www.destatis.de/DE/Themen/Laender-Regionen/Regionales/Gemeindeverzeichnis/Administrativ/02-bundeslaender.html
A16: S6 | B16: Deutscher Olympischer Sportbund [German Olympic Sports Confederation]. Membership survey (as at 1 January 2025), as cited in S1.
A17: S7 | B17: Okabe, M., & Ito, K. (2008). Color Universal Design (CUD): How to make figures and presentations that are friendly to colorblind people. https://jfly.uni-koeln.de/color/
A19: COLOUR PALETTE | B19: Blue #0072B2 / Orange #E69F00 — a pair from the Okabe-Ito palette, distinguishable under deuteranopia, protanopia and tritanopia (S7). Grey #999999 for context data.
A21: SHEET GUIDE
A22: 01_Timeseries | B22: Players, DGV member clubs and facilities 2016–2025, including change
A23: 02_Age_Gender | B23: Age band by gender 2020–2025 (wide format, as published by the DGV)
A24: 03_Age_Long | B24: Same data in long format — source for PivotTables and PivotCharts
A25: 04_States | B25: State golf associations 2022 & 2025, facilities, population, derived metrics
A26: 05_States_Long | B26: State association by age band, long format, for PivotTables
A27: 06_Juniors | B27: Children and juniors 2016–2025 by gender
A28: 07_Seniors | B28: Age group 60 and over in five-year bands, 2025
A29: 08_Federations | B29: Top 15 Olympic sports federations for benchmarking
A30: 09_History | B30: Long-run series of clubs and players, 1951–2025
A31: 10_Metrics | B31: Derived metrics as live formulas (female share, density, growth)
A32: 20_Dashboard | B32: Dashboard with six visualisations
A34: DATA QUALITY | B34: Every table was reconciled against the published row and column totals: age band by gender sums exactly to the published annual total for each year, and the 13 state rows sum to 695,617 (2025) and 682,942 (2022).
... A40: AI DECLARATION | B40: For submission: acknowledge any use of AI tools in the report, per UniSC requirements.

Sheet 01_Timeseries
A1: Players, member clubs and golf facilities, 2016–2025
A2: Source: DGV statistics 2025 (S1)
A4: Year | B4: Players | C4: Change (abs.) | D4: Change (%) | E4: DGV member clubs | F4: Golf facilities | G4: Players per facility | H4: Index (2016 = 100)
A5: 2016 | B5: 643158 | E5: 859 | F5: 732 | G5: =B5/F5 -> 878.63115 | H5: =B5/$B$5*100 -> 100
A6: 2017 | B6: 644943 | C6: =B6-B5 -> 1785 | D6: =IFERROR(C6/B5,"") -> 0.0027753678 | E6: 855 | F6: 731 | G6: =B6/F6 -> 882.27497 | H6: =B6/$B$5*100 -> 100.27754
A7: 2018 | B7: 642240 | C7: =B7-B6 -> -2703 | D7: =IFERROR(C7/B6,"") -> -0.004191068 | E7: 852 | F7: 730 | G7: =B7/F7 -> 879.78082 | H7: =B7/$B$5*100 -> 99.857267
A8: 2019 | B8: 642677 | C8: =B8-B7 -> 437 | D8: =IFERROR(C8/B7,"") -> 0.00068043099 | E8: 845 | F8: 722 | G8: =B8/F8 -> 890.13435 | H8: =B8/$B$5*100 -> 99.925213
A9: 2020 | B9: 651417 | C9: =B9-B8 -> 8740 | D9: =IFERROR(C9/B8,"") -> 0.013599366 | E9: 837 | F9: 720 | G9: =B9/F9 -> 904.74583 | H9: =B9/$B$5*100 -> 101.28413
A10: 2021 | B10: 673983 | C10: =B10-B9 -> 22566 | D10: =IFERROR(C10/B9,"") -> 0.034641405 | E10: 837 | F10: 720 | G10: =B10/F10 -> 936.0875 | H10: =B10/$B$5*100 -> 104.79276
A11: 2022 | B11: 682942 | C11: =B11-B10 -> 8959 | D11: =IFERROR(C11/B10,"") -> 0.01329262 | E11: 838 | F11: 729 | G11: =B11/F11 -> 936.8203 | H11: =B11/$B$5*100 -> 106.18573
A12: 2023 | B12: 682126 | C12: =B12-B11 -> -816 | D12: =IFERROR(C12/B11,"") -> -0.0011948306 | E12: 832 | F12: 725 | G12: =B12/F12 -> 940.86345 | H12: =B12/$B$5*100 -> 106.05885
A13: 2024 | B13: 686708 | C13: =B13-B12 -> 4582 | D13: =IFERROR(C13/B12,"") -> 0.0067172341 | E13: 832 | F13: 726 | G13: =B13/F13 -> 945.87879 | H13: =B13/$B$5*100 -> 106.77128
A14: 2025 | B14: 695617 | C14: =B14-B13 -> 8909 | D14: =IFERROR(C14/B13,"") -> 0.012973491 | E14: 823 | F14: 721 | G14: =B14/F14 -> 964.79473 | H14: =B14/$B$5*100 -> 108.15647

Sheet 02_Age_Gender
A1: Players by age band and gender, 2020–2025
A2: Source: DGV statistics 2022 and 2025 (S1, S3)
A4: Age band | B4: 2020 | E4: 2021 | H4: 2022 | K4: 2023 | N4: 2024 | Q4: 2025
A5: Age band | B5: Male | C5: Female | D5: Total | E5: Male | F5: Female | G5: Total | H5: Male | I5: Female | J5: Total | K5: Male | L5: Female | M5: Total | N5: Male | O5: Female | P5: Total | Q5: Male | R5: Female | S5: Total
A6: Up to 6 | B6: 1186 | C6: 754 | D6: =B6+C6 -> 1940 | E6: 1310 | F6: 861 | G6: =E6+F6 -> 2171 | H6: 1326 | I6: 886 | J6: =H6+I6 -> 2212 | K6: 1265 | L6: 865 | M6: =K6+L6 -> 2130 | N6: 1334 | O6: 855 | P6: =N6+O6 -> 2189 | Q6: 1347 | R6: 824 | S6: =Q6+R6 -> 2171
A7: 7 to 14 | B7: 14729 | C7: 7726 | D7: =B7+C7 -> 22455 | E7: 15438 | F7: 8137 | G7: =E7+F7 -> 23575 | H7: 15302 | I7: 8228 | J7: =H7+I7 -> 23530 | K7: 14582 | L7: 7791 | M7: =K7+L7 -> 22373 | N7: 14137 | O7: 7655 | P7: =N7+O7 -> 21792 | Q7: 14268 | R7: 7472 | S7: =Q7+R7 -> 21740
A8: 15 to 18 | B8: 11761 | C8: 5056 | D8: =B8+C8 -> 16817 | E8: 12612 | F8: 5560 | G8: =E8+F8 -> 18172 | H8: 12769 | I8: 5766 | J8: =H8+I8 -> 18535 | K8: 12676 | L8: 5680 | M8: =K8+L8 -> 18356 | N8: 12704 | O8: 5562 | P8: =N8+O8 -> 18266 | Q8: 13350 | R8: 5537 | S8: =Q8+R8 -> 18887
A9: 19 to 20 | B9: 5371 | C9: 2048 | D9: =B9+C9 -> 7419 | E9: 5744 | F9: 2171 | G9: =E9+F9 -> 7915 | H9: 6136 | I9: 2259 | J9: =H9+I9 -> 8395 | K9: 6372 | L9: 2338 | M9: =K9+L9 -> 8710 | N9: 6595 | O9: 2478 | P9: =N9+O9 -> 9073 | Q9: 7024 | R9: 2498 | S9: =Q9+R9 -> 9522
A10: 21 to 26 | B10: 16396 | C10: 5888 | D10: =B10+C10 -> 22284 | E10: 18583 | F10: 6818 | G10: =E10+F10 -> 25401 | H10: 19744 | I10: 7169 | J10: =H10+I10 -> 26913 | K10: 21136 | L10: 7410 | M10: =K10+L10 -> 28546 | N10: 22933 | O10: 7498 | P10: =N10+O10 -> 30431 | Q10: 24839 | R10: 8060 | S10: =Q10+R10 -> 32899
A11: 27 to 35 | B11: 27102 | C11: 8883 | D11: =B11+C11 -> 35985 | E11: 29800 | F11: 9674 | G11: =E11+F11 -> 39474 | H11: 32083 | I11: 10272 | J11: =H11+I11 -> 42355 | K11: 33711 | L11: 10598 | M11: =K11+L11 -> 44309 | N11: 36261 | O11: 11216 | P11: =N11+O11 -> 47477 | Q11: 39369 | R11: 12016 | S11: =Q11+R11 -> 51385
A12: 36 to 40 | B12: 17853 | C12: 6690 | D12: =B12+C12 -> 24543 | E12: 18346 | F12: 6586 | G12: =E12+F12 -> 24932 | H12: 18886 | I12: 6522 | J12: =H12+I12 -> 25408 | K12: 19125 | L12: 6213 | M12: =K12+L12 -> 25338 | N12: 20100 | O12: 6285 | P12: =N12+O12 -> 26385 | Q12: 21606 | R12: 6399 | S12: =Q12+R12 -> 28005
A13: 41 to 50 | B13: 52795 | C13: 28258 | D13: =B13+C13 -> 81053 | E13: 51990 | F13: 27498 | G13: =E13+F13 -> 79488 | H13: 50959 | I13: 26350 | J13: =H13+I13 -> 77309 | K13: 49188 | L13: 24641 | M13: =K13+L13 -> 73829 | N13: 48359 | O13: 23329 | P13: =N13+O13 -> 71688 | Q13: 48396 | R13: 22454 | S13: =Q13+R13 -> 70850
A14: 51 to 55 | B14: 50885 | C14: 31288 | D14: =B14+C14 -> 82173 | E14: 49901 | F14: 30978 | G14: =E14+F14 -> 80879 | H14: 48560 | I14: 30061 | J14: =H14+I14 -> 78621 | K14: 44944 | L14: 27721 | M14: =K14+L14 -> 72665 | N14: 40824 | O14: 25139 | P14: =N14+O14 -> 65963 | Q14: 37439 | R14: 22880 | S14: =Q14+R14 -> 60319
A15: 56 to 60 | B15: 49696 | C15: 31963 | D15: =B15+C15 -> 81659 | E15: 53246 | F15: 33615 | G15: =E15+F15 -> 86861 | H15: 55916 | I15: 35419 | J15: =H15+I15 -> 91335 | K15: 57646 | L15: 36313 | M15: =K15+L15 -> 93959 | N15: 58289 | O15: 36450 | P15: =N15+O15 -> 94739 | Q15: 57318 | R15: 36368 | S15: =Q15+R15 -> 93686
A16: 61 and over | B16: 168242 | C16: 106847 | D16: =B16+C16 -> 275089 | E16: 174848 | F16: 110267 | G16: =E16+F16 -> 285115 | H16: 176788 | I16: 111541 | J16: =H16+I16 -> 288329 | K16: 179148 | L16: 112763 | M16: =K16+L16 -> 291911 | N16: 183833 | O16: 114872 | P16: =N16+O16 -> 298705 | Q16: 189106 | R16: 117047 | S16: =Q16+R16 -> 306153
A17: Total | B17: =SUM(B6:B16) -> 416016 | C17: =SUM(C6:C16) -> 235401 | D17: =SUM(D6:D16) -> 651417 | E17: =SUM(E6:E16) -> 431818 | F17: =SUM(F6:F16) -> 242165 | G17: =SUM(G6:G16) -> 673983 | H17: =SUM(H6:H16) -> 438469 | I17: =SUM(I6:I16) -> 244473 | ... S17: =SUM(S6:S16) -> 695617

Sheet 03_Age_Long
A1: Age structure, long format
A2: Source for PivotTables and PivotCharts — Insert > PivotTable
A4: Year | B4: Age band | C4: Age rank | D4: Gender | E4: Players
A5: 2020 | B5: Up to 6 | C5: 1 | D5: Male | E5: 1186
A6: 2020 | B6: Up to 6 | C6: 1 | D6: Female | E6: 754
A7: 2020 | B7: 7 to 14 | C7: 2 | D7: Male | E7: 14729
A8: 2020 | B8: 7 to 14 | C8: 2 | D8: Female | E8: 7726
A9: 2020 | B9: 15 to 18 | C9: 3 | D9: Male | E9: 11761
A10: 2020 | B10: 15 to 18 | C10: 3 | D10: Female | E10: 5056
A11: 2020 | B11: 19 to 20 | C11: 4 | D11: Male | E11: 5371
A12: 2020 | B12: 19 to 20 | C12: 4 | D12: Female | E12: 2048
A13: 2020 | B13: 21 to 26 | C13: 5 | D13: Male | E13: 16396
A14: 2020 | B14: 21 to 26 | C14: 5 | D14: Female | E14: 5888
A15: 2020 | B15: 27 to 35 | C15: 6 | D15: Male | E15: 27102
A16: 2020 | B16: 27 to 35 | C16: 6 | D16: Female | E16: 8883
... A136: 2025 | B136: 61 and over | C136: 11 | D136: Female | E136: 117047

Sheet 04_States
A1: State golf associations: participation, growth and market penetration
A2: Players: DGV, 30 Sep; facilities: DGV, 31 Dec 2025; population: Destatis, 2022 Census, as at 31 Dec 2024 (S1, S3, S5)
A4: State golf association | B4: Players 2025 | C4: Players 2022 | D4: Change (abs.) | E4: Change (%) | F4: Male 2025 | G4: Female 2025 | H4: Female share | I4: Facilities | J4: DGV member clubs | K4: Population | L4: Players per 1,000 pop. | M4: Players per facility | N4: Population per facility
A5: Baden-Württemberg | B5: 76079 | C5: 77785 | D5: =B5-C5 -> -1706 | E5: =IFERROR(D5/C5,"") -> -0.021932249 | F5: 48708 | G5: 27371 | H5: =G5/B5 -> 0.35977076 | I5: 89 | J5: 100 | K5: 11245898 | L5: =B5/K5*1000 -> 6.7650445 | M5: =IFERROR(B5/I5,"") -> 854.82022 | N5: =IFERROR(K5/I5,"") -> 126358.4
A6: Bayern | B6: 144501 | C6: 143826 | D6: =B6-C6 -> 675 | E6: =IFERROR(D6/C6,"") -> 0.0046931709 | F6: 92486 | G6: 52015 | H6: =G6/B6 -> 0.35996291 | I6: 171 | J6: 195 | K6: 13248928 | L6: =B6/K6*1000 -> 10.906618 | M6: =IFERROR(B6/I6,"") -> 845.03509 | N6: =IFERROR(K6/I6,"") -> 77479.111
A7: Berlin/Brandenburg | B7: 27777 | C7: 27491 | D7: =B7-C7 -> 286 | E7: =IFERROR(D7/C7,"") -> 0.010403405 | F7: 18775 | G7: 9002 | H7: =G7/B7 -> 0.32408107 | I7: 19 | J7: 27 | K7: 6242012 | L7: =B7/K7*1000 -> 4.4500075 | M7: =IFERROR(B7/I7,"") -> 1461.9474 | N7: =IFERROR(K7/I7,"") -> 328526.95
A8: Hamburg | B8: 22099 | C8: 21872 | D8: =B8-C8 -> 227 | E8: =IFERROR(D8/C8,"") -> 0.010378566 | F8: 13936 | G8: 8163 | H8: =G8/B8 -> 0.36938323 | I8: 19 | J8: 21 | K8: 1862565 | L8: =B8/K8*1000 -> 11.864821 | M8: =IFERROR(B8/I8,"") -> 1163.1053 | N8: =IFERROR(K8/I8,"") -> 98029.737
A9: Hessen | B9: 49741 | C9: 50920 | D9: =B9-C9 -> -1179 | E9: =IFERROR(D9/C9,"") -> -0.023153967 | F9: 32266 | G9: 17475 | H9: =G9/B9 -> 0.35131984 | I9: 53 | J9: 64 | K9: 6280793 | L9: =B9/K9*1000 -> 7.9195414 | M9: =IFERROR(B9/I9,"") -> 938.50943 | N9: =IFERROR(K9/I9,"") -> 118505.53
A10: Mecklenburg-Vorpommern | B10: 18752 | C10: 18419 | D10: =B10-C10 -> 333 | E10: =IFERROR(D10/C10,"") -> 0.018079157 | F10: 12251 | G10: 6501 | H10: =G10/B10 -> 0.34668302 | I10: 17 | J10: 20 | K10: 1573597 | L10: =B10/K10*1000 -> 11.916647 | M10: =IFERROR(B10/I10,"") -> 1103.0588 | N10: =IFERROR(K10/I10,"") -> 92564.529
A11: Niedersachsen/Bremen | B11: 78772 | C11: 74161 | D11: =B11-C11 -> 4611 | E11: =IFERROR(D11/C11,"") -> 0.062175537 | F11: 52184 | G11: 26588 | H11: =G11/B11 -> 0.3375311 | I11: 78 | J11: 84 | K11: 8709370 | L11: =B11/K11*1000 -> 9.0445118 | M11: =IFERROR(B11/I11,"") -> 1009.8974 | N11: =IFERROR(K11/I11,"") -> 111658.59
A12: Nordrhein-Westfalen | B12: 144750 | C12: 142809 | D12: =B12-C12 -> 1941 | E12: =IFERROR(D12/C12,"") -> 0.01359158 | F12: 94837 | G12: 49913 | H12: =G12/B12 -> 0.34482211 | I12: 157 | J12: 172 | K12: 18034454 | L12: =B12/K12*1000 -> 8.0263034 | M12: =IFERROR(B12/I12,"") -> 921.97452 | N12: =IFERROR(K12/I12,"") -> 114869.13
A13: Rheinland-Pfalz/Saarland | B13: 30113 | C13: 30854 | D13: =B13-C13 -> -741 | E13: =IFERROR(D13/C13,"") -> -0.024016335 | F13: 19803 | G13: 10310 | H13: =G13/B13 -> 0.34237705 | I13: 39 | J13: 44 | K13: 5141710 | L13: =B13/K13*1000 -> 5.8566119 | M13: =IFERROR(B13/I13,"") -> 772.12821 | N13: =IFERROR(K13/I13,"") -> 131838.72
A14: Sachsen-Anhalt | B14: 2168 | C14: 2145 | D14: =B14-C14 -> 23 | E14: =IFERROR(D14/C14,"") -> 0.010722611 | F14: 1113 | G14: 1055 | H14: =G14/B14 -> 0.48662362 | I14: 5 | J14: 5 | K14: 2135597 | L14: =B14/K14*1000 -> 1.0151728 | M14: =IFERROR(B14/I14,"") -> 433.6 | N14: =IFERROR(K14/I14,"") -> 427119.4
A15: Sachsen/Thüringen | B15: 13696 | C15: 13201 | D15: =B15-C15 -> 495 | E15: =IFERROR(D15/C15,"") -> 0.037497159 | F15: 9222 | G15: 4474 | H15: =G15/B15 -> 0.32666472 | I15: 21 | J15: 28 | K15: 6142699 | L15: =B15/K15*1000 -> 2.2296388 | M15: =IFERROR(B15/I15,"") -> 652.19048 | N15: =IFERROR(K15/I15,"") -> 292509.48
A16: Schleswig-Holstein | B16: 54471 | C16: 53822 | D16: =B16-C16 -> 649 | E16: =IFERROR(D16/C16,"") -> 0.012058266 | F16: 35144 | G16: 19327 | H16: =G16/B16 -> 0.35481265 | I16: 53 | J16: 62 | K16: 2959517 | L16: =B16/K16*1000 -> 18.405368 | M16: =IFERROR(B16/I16,"") -> 1027.7547 | N16: =IFERROR(K16/I16,"") -> 55839.943
A17: VcG (non-club members, nationwide) | B17: 32698 | C17: 25637 | D17: =B17-C17 -> 7061 | E17: =IFERROR(D17/C17,"") -> 0.27542224 | F17: 23337 | G17: 9361 | H17: =G17/B17 -> 0.28628662 | I17: 0 | J17: 1 | K17: n/a | L17: n/a | M17: =IFERROR(B17/I17,"") | N17: n/a
A18: Total | B18: =SUM(B5:B17) -> 695617 | C18: =SUM(C5:C17) -> 682942 | D18: =SUM(D5:D17) -> 12675 | E18: =D18/C18 -> 0.018559409 | F18: =SUM(F5:F17) -> 454062 | G18: =SUM(G5:G17) -> 241555 | H18: =G18/B18 -> 0.34725287 | I18: =SUM(I5:I17) -> 721 | J18: =SUM(J5:J17) -> 823
A20: Note: VcG is a nationwide membership category, not a region. Exclude it from maps, density metrics and regional comparisons.
A22: Golf facilities by course size (31 December 2025)
A23: State golf association | B23: 9-hole | C23: 18-hole | D23: 27-hole | E23: Total
A24: Baden-Württemberg | B24: 18 | C24: 52 | D24: 19 | E24: 89
A25: Bayern | B25: 43 | C25: 107 | D25: 21 | E25: 171
A26: Berlin/Brandenburg | B26: 4 | C26: 2 | D26: 13 | E26: 19
A27: Hamburg | B27: 3 | C27: 11 | D27: 5 | E27: 19
A28: Hessen | B28: 10 | C28: 30 | D28: 13 | E28: 53
A29: Mecklenburg-Vorpommern | B29: 4 | C29: 6 | D29: 7 | E29: 17
A30: Niedersachsen/Bremen | B30: 11 | C30: 53 | D30: 14 | E30: 78
A31: Nordrhein-Westfalen | B31: 28 | C31: 104 | D31: 25 | E31: 157
A32: Rheinland-Pfalz/Saarland | B32: 5 | C32: 27 | D32: 7 | E32: 39
A33: Sachsen-Anhalt | B33: 3 | C33: 2 | D33: 0 | E33: 5
A34: Sachsen/Thüringen | B34: 7 | C34: 12 | D34: 2 | E34: 21
A35: Schleswig-Holstein | B35: 7 | C35: 31 | D35: 15 | E35: 53
A36: Total | B36: =SUM(B24:B35) -> 143 | C36: =SUM(C24:C35) -> 437 | D36: =SUM(D24:D35) -> 141 | E36: =SUM(E24:E35) -> 721

Sheet 05_States_Long
A1: State golf association by age band, long format
A2: Source for PivotTables and PivotCharts
A4: Year | B4: State golf association | C4: Age band | D4: Age rank | E4: Players
A5: 2022 | B5: Baden-Württemberg | C5: Up to 6 | D5: 1 | E5: 331
A6: 2022 | B6: Baden-Württemberg | C6: 7 to 14 | D6: 2 | E6: 3370
A7: 2022 | B7: Baden-Württemberg | C7: 15 to 18 | D7: 3 | E7: 2595
A8: 2022 | B8: Baden-Württemberg | C8: 19 to 20 | D8: 4 | E8: 1114
A9: 2022 | B9: Baden-Württemberg | C9: 21 to 26 | D9: 5 | E9: 3420
A10: 2022 | B10: Baden-Württemberg | C10: 27 to 35 | D10: 6 | E10: 4252
A11: 2022 | B11: Baden-Württemberg | C11: 36 to 40 | D11: 7 | E11: 2336
A12: 2022 | B12: Baden-Württemberg | C12: 41 to 50 | D12: 8 | E12: 7223
A13: 2022 | B13: Baden-Württemberg | C13: 51 to 55 | D13: 9 | E13: 7684
A14: 2022 | B14: Baden-Württemberg | C14: 56 to 60 | D14: 10 | E14: 9784
A15: 2022 | B15: Baden-Württemberg | C15: 61 and over | D15: 11 | E15: 35676
A16: 2022 | B16: Bayern | C16: Up to 6 | D16: 1 | E16: 616
... A290: 2025 | B290: VcG (non-club members, nationwide) | C290: 61 and over | D290: 11 | E290: 8930

Sheet 06_Juniors
A1: Children and juniors, 2016–2025
A2: Source: DGV statistics 2025 (S1)
B4: Up to 6 | D4: 7 to 14 | F4: 15 to 18 | H4: Total
A5: Year | B5: M | C5: F | D5: M | E5: F | F5: M | G5: F | H5: Male | I5: Female | J5: Total | K5: Female share
A6: 2016 | B6: 1170 | C6: 703 | D6: 16114 | E6: 8202 | F6: 12578 | G6: 5186 | H6: =B6+D6+F6 -> 29862 | I6: =C6+E6+G6 -> 14091 | J6: =H6+I6 -> 43953 | K6: =I6/J6 -> 0.32059245
A7: 2017 | B7: 1112 | C7: 670 | D7: 15727 | E7: 7994 | F7: 12093 | G7: 5077 | H7: =B7+D7+F7 -> 28932 | I7: =C7+E7+G7 -> 13741 | J7: =H7+I7 -> 42673 | K7: =I7/J7 -> 0.32200689
A8: 2018 | B8: 1122 | C8: 701 | D8: 15133 | E8: 7887 | F8: 11643 | G8: 4919 | H8: =B8+D8+F8 -> 27898 | I8: =C8+E8+G8 -> 13507 | J8: =H8+I8 -> 41405 | K8: =I8/J8 -> 0.32621664
A9: 2019 | B9: 1058 | C9: 726 | D9: 14782 | E9: 7608 | F9: 11368 | G9: 4796 | H9: =B9+D9+F9 -> 27208 | I9: =C9+E9+G9 -> 13130 | J9: =H9+I9 -> 40338 | K9: =I9/J9 -> 0.32549953
A10: 2020 | B10: 1186 | C10: 754 | D10: 14729 | E10: 7726 | F10: 11761 | G10: 5056 | H10: =B10+D10+F10 -> 27676 | I10: =C10+E10+G10 -> 13536 | J10: =H10+I10 -> 41212 | K10: =I10/J10 -> 0.32844802
A11: 2021 | B11: 1310 | C11: 861 | D11: 15438 | E11: 8137 | F11: 12612 | G11: 5560 | H11: =B11+D11+F11 -> 29360 | I11: =C11+E11+G11 -> 14558 | J11: =H11+I11 -> 43918 | K11: =I11/J11 -> 0.3314814
A12: 2022 | B12: 1326 | C12: 886 | D12: 15302 | E12: 8228 | F12: 12769 | G12: 5766 | H12: =B12+D12+F12 -> 29397 | I12: =C12+E12+G12 -> 14880 | J12: =H12+I12 -> 44277 | K12: =I12/J12 -> 0.33606613
A13: 2023 | B13: 1265 | C13: 865 | D13: 14582 | E13: 7791 | F13: 12676 | G13: 5680 | H13: =B13+D13+F13 -> 28523 | I13: =C13+E13+G13 -> 14336 | J13: =H13+I13 -> 42859 | K13: =I13/J13 -> 0.33449217
A14: 2024 | B14: 1334 | C14: 855 | D14: 14137 | E14: 7655 | F14: 12704 | G14: 5562 | H14: =B14+D14+F14 -> 28175 | I14: =C14+E14+G14 -> 14072 | J14: =H14+I14 -> 42247 | K14: =I14/J14 -> 0.33308874
A15: 2025 | B15: 1347 | C15: 824 | D15: 14268 | E15: 7472 | F15: 13350 | G15: 5537 | H15: =B15+D15+F15 -> 28965 | I15: =C15+E15+G15 -> 13833 | J15: =H15+I15 -> 42798 | K15: =I15/J15 -> 0.32321604

Sheet 07_Seniors
A1: Players aged 60 and over, 2025
A2: Source: DGV statistics 2025 (S1). Note: overlaps with the '61 and over' band on sheet 02 — do not add.
A4: Age band | B4: Female | C4: Male | D4: Total | E4: Share of all players | F4: Female share
A5: 60 to 64 | B5: 35404 | C5: 57299 | D5: =B5+C5 -> 92703 | E5: 0.133 | F5: =B5/D5 -> 0.38190781
A6: 65 to 69 | B6: 28329 | C6: 44389 | D6: =B6+C6 -> 72718 | E6: 0.105 | F6: =B6/D6 -> 0.38957342
A7: 70 to 74 | B7: 24021 | C7: 36869 | D7: =B7+C7 -> 60890 | E7: 0.088 | F7: =B7/D7 -> 0.39449828
A8: 75 to 79 | B8: 19265 | C8: 30313 | D8: =B8+C8 -> 49578 | E8: 0.071 | F8: =B8/D8 -> 0.38857961
A9: 80 and over | B9: 17555 | C9: 32299 | D9: =B9+C9 -> 49854 | E9: 0.072 | F9: =B9/D9 -> 0.35212821
A10: Total 60 and over | B10: =SUM(B5:B9) -> 124574 | C10: =SUM(C5:C9) -> 201169 | D10: =SUM(D5:D9) -> 325743 | E10: =SUM(E5:E9) -> 0.469

Sheet 08_Federations
A1: Top 15 Olympic sports federations in Germany
A2: As at 1 January 2025 (2024 data), cited in DGV statistics 2025 (S1, S6)
A4: Rank | B4: Sports federation | C4: Members | D4: Change (abs.) | E4: Change (%)
A5: 1 | B5: German Football Association | C5: 8005050 | D5: 297843 | E5: 0.039
A6: 2 | B6: German Gymnastics Federation | C6: 5246046 | D6: 182474 | E6: 0.036
A7: 3 | B7: German Tennis Federation | C7: 1518566 | D7: 27180 | E7: 0.018
A8: 4 | B8: German Alpine Club | C8: 1517087 | D8: 44776 | E8: 0.03
A9: 5 | B9: German Shooting Federation | C9: 1349758 | D9: 11918 | E9: 0.009
A10: 6 | B10: German Athletics Federation | C10: 804129 | D10: 11364 | E10: 0.014
A11: 7 | B11: German Handball Federation | C11: 793149 | D11: 27781 | E11: 0.036
A12: 8 | B12: German Golf Federation (DGV) | C12: 686708 | D12: 4582 | E12: 0.007
A13: 9 | B13: German Equestrian Federation | C13: 657994 | D13: -4932 | E13: -0.007
A14: 10 | B14: German Life Saving Association | C14: 626161 | D14: 19844 | E14: 0.033
A15: 11 | B15: German Swimming Federation | C15: 602724 | D15: 14286 | E15: 0.024
A16: 12 | B16: German Table Tennis Federation | C16: 542063 | D16: 14763 | E16: 0.028
... A19: 15 | B19: German Volleyball Federation | C19: 464148 | D19: 27800 | E19: 0.064

Sheet 09_History
A1: Long-run series: clubs and players, 1951–2025
A2: Source: DGV statistics 2025 (S1)
A4: Year | B4: Clubs | C4: Players | D4: Players per club
A5: 1951 | B5: 39 | C5: 2700 | D5: =C5/B5 -> 69.230769
A6: 1952 | B6: 38 | C6: 3400 | D6: =C6/B6 -> 89.473684
A7: 1953 | B7: 41 | C7: 4000 | D7: =C7/B7 -> 97.560976
A8: 1954 | B8: 41 | C8: 4100 | D8: =C8/B8 -> 100
A9: 1955 | B9: 57 | C9: 5000 | D9: =C9/B9 -> 87.719298
A10: 1956 | B10: 50 | C10: 5500 | D10: =C10/B10 -> 110
A11: 1957 | B11: 51 | C11: 6300 | D11: =C11/B11 -> 123.52941
A12: 1958 | B12: 54 | C12: 7000 | D12: =C12/B12 -> 129.62963
A13: 1959 | B13: 58 | C13: 7800 | D13: =C13/B13 -> 134.48276
A14: 1960 | B14: 62 | C14: 9200 | D14: =C14/B14 -> 148.3871
A15: 1961 | B15: 65 | C15: 10400 | D15: =C15/B15 -> 160
A16: 1962 | B16: 73 | C16: 11200 | D16: =C16/B16 -> 153.42466
... A79: 2025 | B79: 812 | C79: 695617 | D79: =C79/B79 -> 856.67118

Sheet 10_Metrics
A1: Derived metrics
A2: All values are live formulas pointing at the data sheets — edit the raw data and these update
A4: A) Gender balance over time
A5: Year | B5: Male | C5: Female | D5: Total | E5: Female share | F5: Change in share (pp)
A6: 2020 | B6: =SUM('02_Age_Gender'!B6:B16) -> 416016 | C6: =SUM('02_Age_Gender'!C6:C16) -> 235401 | D6: =B6+C6 -> 651417 | E6: =C6/D6 -> 0.3613676
A7: 2021 | B7: =SUM('02_Age_Gender'!E6:E16) -> 431818 | C7: =SUM('02_Age_Gender'!F6:F16) -> 242165 | D7: =B7+C7 -> 673983 | E7: =C7/D7 -> 0.35930431 | F7: =(E7-E6)*100 -> -0.20632884
A8: 2022 | B8: =SUM('02_Age_Gender'!H6:H16) -> 438469 | C8: =SUM('02_Age_Gender'!I6:I16) -> 244473 | D8: =B8+C8 -> 682942 | E8: =C8/D8 -> 0.35797037 | F8: =(E8-E7)*100 -> -0.13339454
A9: 2023 | B9: =SUM('02_Age_Gender'!K6:K16) -> 439793 | C9: =SUM('02_Age_Gender'!L6:L16) -> 242333 | D9: =B9+C9 -> 682126 | E9: =C9/D9 -> 0.35526134 | F9: =(E9-E8)*100 -> -0.27090247
A10: 2024 | B10: =SUM('02_Age_Gender'!N6:N16) -> 445369 | C10: =SUM('02_Age_Gender'!O6:O16) -> 241339 | D10: =B10+C10 -> 686708 | E10: =C10/D10 -> 0.35144341 | F10: =(E10-E9)*100 -> -0.38179364
A11: 2025 | B11: =SUM('02_Age_Gender'!Q6:Q16) -> 454062 | C11: =SUM('02_Age_Gender'!R6:R16) -> 241555 | D11: =B11+C11 -> 695617 | E11: =C11/D11 -> 0.34725287 | F11: =(E11-E10)*100 -> -0.41905378
A14: B) Growth by age band, 2022 to 2025
A15: Age band | B15: 2022 | C15: 2025 | D15: Change (abs.) | E15: Change (%) | F15: Share of total 2025 | G15: Contribution to net growth
A16: Up to 6 | B16: ='02_Age_Gender'!J6 -> 2212 | C16: ='02_Age_Gender'!S6 -> 2171 | D16: =C16-B16 -> -41 | E16: =D16/B16 -> -0.018535262 | F16: =C16/SUM($C$16:$C$26) -> 0.0031209703 | G16: =D16/SUM($D$16:$D$26) -> -0.003234714
A17: 7 to 14 | B17: ='02_Age_Gender'!J7 -> 23530 | C17: ='02_Age_Gender'!S7 -> 21740 | D17: =C17-B17 -> -1790 | E17: =D17/B17 -> -0.076073098 | F17: =C17/SUM($C$16:$C$26) -> 0.03125283 | G17: =D17/SUM($D$16:$D$26) -> -0.14122288
A18: 15 to 18 | B18: ='02_Age_Gender'!J8 -> 18535 | C18: ='02_Age_Gender'!S8 -> 18887 | D18: =C18-B18 -> 352 | E18: =D18/B18 -> 0.018991098 | F18: =C18/SUM($C$16:$C$26) -> 0.027151435 | G18: =D18/SUM($D$16:$D$26) -> 0.027771203
A19: 19 to 20 | B19: ='02_Age_Gender'!J9 -> 8395 | C19: ='02_Age_Gender'!S9 -> 9522 | D19: =C19-B19 -> 1127 | E19: =D19/B19 -> 0.13424658 | F19: =C19/SUM($C$16:$C$26) -> 0.013688567 | G19: =D19/SUM($D$16:$D$26) -> 0.088915187
A20: 21 to 26 | B20: ='02_Age_Gender'!J10 -> 26913 | C20: ='02_Age_Gender'!S10 -> 32899 | D20: =C20-B20 -> 5986 | E20: =D20/B20 -> 0.22242039 | F20: =C20/SUM($C$16:$C$26) -> 0.047294704 | G20: =D20/SUM($D$16:$D$26) -> 0.47226824
A21: 27 to 35 | B21: ='02_Age_Gender'!J11 -> 42355 | C21: ='02_Age_Gender'!S11 -> 51385 | D21: =C21-B21 -> 9030 | E21: =D21/B21 -> 0.21319797 | F21: =C21/SUM($C$16:$C$26) -> 0.073869673 | G21: =D21/SUM($D$16:$D$26) -> 0.71242604
A22: 36 to 40 | B22: ='02_Age_Gender'!J12 -> 25408 | C22: ='02_Age_Gender'!S12 -> 28005 | D22: =C22-B22 -> 2597 | E22: =D22/B22 -> 0.1022119 | F22: =C22/SUM($C$16:$C$26) -> 0.040259223 | G22: =D22/SUM($D$16:$D$26) -> 0.20489152
A23: 41 to 50 | B23: ='02_Age_Gender'!J13 -> 77309 | C23: ='02_Age_Gender'!S13 -> 70850 | D23: =C23-B23 -> -6459 | E23: =D23/B23 -> -0.08354784 | F23: =C23/SUM($C$16:$C$26) -> 0.10185202 | G23: =D23/SUM($D$16:$D$26) -> -0.5095858
A24: 51 to 55 | B24: ='02_Age_Gender'!J14 -> 78621 | C24: ='02_Age_Gender'!S14 -> 60319 | D24: =C24-B24 -> -18302 | E24: =D24/B24 -> -0.23278768 | F24: =C24/SUM($C$16:$C$26) -> 0.086712947 | G24: =D24/SUM($D$16:$D$26) -> -1.4439448
A25: 56 to 60 | B25: ='02_Age_Gender'!J15 -> 91335 | C25: ='02_Age_Gender'!S15 -> 93686 | D25: =C25-B25 -> 2351 | E25: =D25/B25 -> 0.025740406 | F25: =C25/SUM($C$16:$C$26) -> 0.13468043 | G25: =D25/SUM($D$16:$D$26) -> 0.18548323
A26: 61 and over | B26: ='02_Age_Gender'!J16 -> 288329 | C26: ='02_Age_Gender'!S16 -> 306153 | D26: =C26-B26 -> 17824 | E26: =D26/B26 -> 0.06181827 | F26: =C26/SUM($C$16:$C$26) -> 0.44011719 | G26: =D26/SUM($D$16:$D$26) -> 1.4062327
A29: C) Market penetration by state association (VcG excluded)
A30: State golf association | B30: Players 2025 | C30: Population | D30: Players per 1,000 pop. | E30: Change (%) 2022–25 | F30: Female share | G30: Density rank
A31: ='04_States'!A5 -> Baden-Württemberg | B31: ='04_States'!B5 -> 76079 | C31: ='04_States'!K5 -> 11245898 | D31: =B31/C31*1000 -> 6.7650445 | E31: ='04_States'!E5 -> -0.021932249 | F31: ='04_States'!H5 -> 0.35977076 | G31: =RANK(D31,$D$31:$D$42) -> 8
A32: ='04_States'!A6 -> Bayern | B32: ='04_States'!B6 -> 144501 | C32: ='04_States'!K6 -> 13248928 | D32: =B32/C32*1000 -> 10.906618 | E32: ='04_States'!E6 -> 0.0046931709 | F32: ='04_States'!H6 -> 0.35996291 | G32: =RANK(D32,$D$31:$D$42) -> 4
A33: ='04_States'!A7 -> Berlin/Brandenburg | B33: ='04_States'!B7 -> 27777 | C33: ='04_States'!K7 -> 6242012 | D33: =B33/C33*1000 -> 4.4500075 | E33: ='04_States'!E7 -> 0.010403405 | F33: ='04_States'!H7 -> 0.32408107 | G33: =RANK(D33,$D$31:$D$42) -> 10
A34: ='04_States'!A8 -> Hamburg | B34: ='04_States'!B8 -> 22099 | C34: ='04_States'!K8 -> 1862565 | D34: =B34/C34*1000 -> 11.864821 | E34: ='04_States'!E8 -> 0.010378566 | F34: ='04_States'!H8 -> 0.36938323 | G34: =RANK(D34,$D$31:$D$42) -> 3
A35: ='04_States'!A9 -> Hessen | B35: ='04_States'!B9 -> 49741 | C35: ='04_States'!K9 -> 6280793 | D35: =B35/C35*1000 -> 7.9195414 | E35: ='04_States'!E9 -> -0.023153967 | F35: ='04_States'!H9 -> 0.35131984 | G35: =RANK(D35,$D$31:$D$42) -> 7
A36: ='04_States'!A10 -> Mecklenburg-Vorpommern | B36: ='04_States'!B10 -> 18752 | C36: ='04_States'!K10 -> 1573597 | D36: =B36/C36*1000 -> 11.916647 | E36: ='04_States'!E10 -> 0.018079157 | F36: ='04_States'!H10 -> 0.34668302 | G36: =RANK(D36,$D$31:$D$42) -> 2
A37: ='04_States'!A11 -> Niedersachsen/Bremen | B37: ='04_States'!B11 -> 78772 | C37: ='04_States'!K11 -> 8709370 | D37: =B37/C37*1000 -> 9.0445118 | E37: ='04_States'!E11 -> 0.062175537 | F37: ='04_States'!H11 -> 0.3375311 | G37: =RANK(D37,$D$31:$D$42) -> 5
A38: ='04_States'!A12 -> Nordrhein-Westfalen | B38: ='04_States'!B12 -> 144750 | C38: ='04_States'!K12 -> 18034454 | D38: =B38/C38*1000 -> 8.0263034 | E38: ='04_States'!E12 -> 0.01359158 | F38: ='04_States'!H12 -> 0.34482211 | G38: =RANK(D38,$D$31:$D$42) -> 6
A39: ='04_States'!A13 -> Rheinland-Pfalz/Saarland | B39: ='04_States'!B13 -> 30113 | C39: ='04_States'!K13 -> 5141710 | D39: =B39/C39*1000 -> 5.8566119 | E39: ='04_States'!E13 -> -0.024016335 | F39: ='04_States'!H13 -> 0.34237705 | G39: =RANK(D39,$D$31:$D$42) -> 9
A40: ='04_States'!A14 -> Sachsen-Anhalt | B40: ='04_States'!B14 -> 2168 | C40: ='04_States'!K14 -> 2135597 | D40: =B40/C40*1000 -> 1.0151728 | E40: ='04_States'!E14 -> 0.010722611 | F40: ='04_States'!H14 -> 0.48662362 | G40: =RANK(D40,$D$31:$D$42) -> 12
A41: ='04_States'!A15 -> Sachsen/Thüringen | B41: ='04_States'!B15 -> 13696 | C41: ='04_States'!K15 -> 6142699 | D41: =B41/C41*1000 -> 2.2296388 | E41: ='04_States'!E15 -> 0.037497159 | F41: ='04_States'!H15 -> 0.32666472 | G41: =RANK(D41,$D$31:$D$42) -> 11
A42: ='04_States'!A16 -> Schleswig-Holstein | B42: ='04_States'!B16 -> 54471 | C42: ='04_States'!K16 -> 2959517 | D42: =B42/C42*1000 -> 18.405368 | E42: ='04_States'!E16 -> 0.012058266 | F42: ='04_States'!H16 -> 0.35481265 | G42: =RANK(D42,$D$31:$D$42) -> 1
A45: D) Headline figures for the KPI tiles
A46: Players 2025 | B46: ='01_Timeseries'!B14 -> 695617
A47: Growth vs 2024 (abs.) | B47: ='01_Timeseries'!C14 -> 8909
...

Sheet 20_Dashboard
B2: GROWING GOLF IN GERMANY — Participation Dashboard 2016–2025
B4: Audience: German Golf Federation (DGV) and golf facility operators | Data as at 30 Sep 2025 (players) / 31 Dec 2025 (facilities) | Sources: DGV; Destatis
B6: PLAYERS 2025 | D6: GROWTH VS 2024 | F6: FEMALE SHARE | H6: AGED 60+ | J6: AGED UNDER 19 | L6: GOLF FACILITIES
B7: ='10_Metrics'!B46 -> 695617 | D7: ='10_Metrics'!B48 -> 0.012973491 | F7: ='10_Metrics'!B49 -> 0.34725287 | H7: ='10_Metrics'!B51 -> 0.46827924 | J7: ='10_Metrics'!B52 -> 0.061525236 | L7: ='10_Metrics'!B53 -> 721
B10: 1 Membership trend 2016–2025 — the COVID surge and what followed | H10: 2 Age structure 2025 by gender — where the membership base actually sits
B28: 3 Growth by age band 2022–2025 — the engine and the leak | H28: 4 Female share 2020–2025 — the quiet decline
B46: 5 Market penetration by state association — where the headroom is | H46: 6 Children and juniors 2016–2025 — the talent pipeline
B65: Colour encoding: blue #0072B2 = male / overall membership, orange #E69F00 = female / attention accent. Palette after Okabe and Ito (2008), distinguishable under all common forms of colour vision deficiency. | Sources: Deutscher Golf Verband (2026); Statistisches Bundesamt (2025). Full details on sheet 00_README.
